2018-01-22 11:03:37,186 [Thread-7:123145437872128] [django.request:118] [exception:handle_uncaught_exception] [ERROR]- Internal Server Error: /projects/new/
Traceback (most recent call last):
  File "/Users/yujie/anaconda3/envs/django2/lib/python3.6/site-packages/django/core/handlers/exception.py", line 35, in inner
    response = get_response(request)
  File "/Users/yujie/anaconda3/envs/django2/lib/python3.6/site-packages/django/core/handlers/base.py", line 139, in _get_response
    "returned None instead." % (callback.__module__, view_name)
ValueError: The view projects.views.NewProjectView didn't return an HttpResponse object. It returned None instead.
2018-01-22 11:26:56,928 [Thread-2:123145338785792] [django.request:118] [exception:handle_uncaught_exception] [ERROR]- Internal Server Error: /projects/Notes/
Traceback (most recent call last):
  File "/Users/yujie/anaconda3/envs/django2/lib/python3.6/site-packages/django/core/handlers/exception.py", line 35, in inner
    response = get_response(request)
  File "/Users/yujie/anaconda3/envs/django2/lib/python3.6/site-packages/django/core/handlers/base.py", line 128, in _get_response
    response = self.process_exception_by_middleware(e, request)
  File "/Users/yujie/anaconda3/envs/django2/lib/python3.6/site-packages/django/core/handlers/base.py", line 126, in _get_response
    response = wrapped_callback(request, *callback_args, **callback_kwargs)
  File "/Users/yujie/anaconda3/envs/django2/lib/python3.6/site-packages/django/views/generic/base.py", line 69, in view
    return self.dispatch(request, *args, **kwargs)
  File "/Users/yujie/anaconda3/envs/django2/lib/python3.6/site-packages/django/views/generic/base.py", line 89, in dispatch
    return handler(request, *args, **kwargs)
TypeError: get() got an unexpected keyword argument 'name'
2018-01-22 11:27:21,441 [Thread-7:123145336860672] [django.request:118] [exception:handle_uncaught_exception] [ERROR]- Internal Server Error: /projects/Notes/
Traceback (most recent call last):
  File "/Users/yujie/anaconda3/envs/django2/lib/python3.6/site-packages/django/core/handlers/exception.py", line 35, in inner
    response = get_response(request)
  File "/Users/yujie/anaconda3/envs/django2/lib/python3.6/site-packages/django/core/handlers/base.py", line 128, in _get_response
    response = self.process_exception_by_middleware(e, request)
  File "/Users/yujie/anaconda3/envs/django2/lib/python3.6/site-packages/django/core/handlers/base.py", line 126, in _get_response
    response = wrapped_callback(request, *callback_args, **callback_kwargs)
  File "/Users/yujie/anaconda3/envs/django2/lib/python3.6/site-packages/django/views/generic/base.py", line 69, in view
    return self.dispatch(request, *args, **kwargs)
  File "/Users/yujie/anaconda3/envs/django2/lib/python3.6/site-packages/django/views/generic/base.py", line 89, in dispatch
    return handler(request, *args, **kwargs)
TypeError: get() got an unexpected keyword argument 'name'
2018-01-22 11:27:42,433 [Thread-8:123145336860672] [django.request:118] [exception:handle_uncaught_exception] [ERROR]- Internal Server Error: /projects/Notes/
Traceback (most recent call last):
  File "/Users/yujie/anaconda3/envs/django2/lib/python3.6/site-packages/django/core/handlers/exception.py", line 35, in inner
    response = get_response(request)
  File "/Users/yujie/anaconda3/envs/django2/lib/python3.6/site-packages/django/core/handlers/base.py", line 128, in _get_response
    response = self.process_exception_by_middleware(e, request)
  File "/Users/yujie/anaconda3/envs/django2/lib/python3.6/site-packages/django/core/handlers/base.py", line 126, in _get_response
    response = wrapped_callback(request, *callback_args, **callback_kwargs)
  File "/Users/yujie/anaconda3/envs/django2/lib/python3.6/site-packages/django/views/generic/base.py", line 69, in view
    return self.dispatch(request, *args, **kwargs)
  File "/Users/yujie/anaconda3/envs/django2/lib/python3.6/site-packages/django/views/generic/base.py", line 89, in dispatch
    return handler(request, *args, **kwargs)
TypeError: get() got an unexpected keyword argument 'name'
2018-01-22 11:31:03,890 [Thread-7:123145545199616] [django.request:118] [exception:handle_uncaught_exception] [ERROR]- Internal Server Error: /projects/Notes/
Traceback (most recent call last):
  File "/Users/yujie/anaconda3/envs/django2/lib/python3.6/site-packages/django/core/handlers/exception.py", line 35, in inner
    response = get_response(request)
  File "/Users/yujie/anaconda3/envs/django2/lib/python3.6/site-packages/django/core/handlers/base.py", line 128, in _get_response
    response = self.process_exception_by_middleware(e, request)
  File "/Users/yujie/anaconda3/envs/django2/lib/python3.6/site-packages/django/core/handlers/base.py", line 126, in _get_response
    response = wrapped_callback(request, *callback_args, **callback_kwargs)
  File "/Users/yujie/anaconda3/envs/django2/lib/python3.6/site-packages/django/views/generic/base.py", line 69, in view
    return self.dispatch(request, *args, **kwargs)
  File "/Users/yujie/anaconda3/envs/django2/lib/python3.6/site-packages/django/views/generic/base.py", line 89, in dispatch
    return handler(request, *args, **kwargs)
TypeError: get() got an unexpected keyword argument 'project_name'
2018-01-22 12:16:35,340 [Thread-7:123145515888640] [django.request:118] [exception:handle_uncaught_exception] [ERROR]- Internal Server Error: /projects/Notes/
Traceback (most recent call last):
  File "/Users/yujie/anaconda3/envs/django2/lib/python3.6/site-packages/django/core/handlers/exception.py", line 35, in inner
    response = get_response(request)
  File "/Users/yujie/anaconda3/envs/django2/lib/python3.6/site-packages/django/core/handlers/base.py", line 128, in _get_response
    response = self.process_exception_by_middleware(e, request)
  File "/Users/yujie/anaconda3/envs/django2/lib/python3.6/site-packages/django/core/handlers/base.py", line 126, in _get_response
    response = wrapped_callback(request, *callback_args, **callback_kwargs)
  File "/Users/yujie/anaconda3/envs/django2/lib/python3.6/site-packages/django/views/generic/base.py", line 69, in view
    return self.dispatch(request, *args, **kwargs)
  File "/Users/yujie/anaconda3/envs/django2/lib/python3.6/site-packages/django/views/generic/base.py", line 89, in dispatch
    return handler(request, *args, **kwargs)
TypeError: get() got an unexpected keyword argument 'project_name'
2018-01-22 12:16:59,706 [Thread-7:123145329389568] [django.request:118] [exception:handle_uncaught_exception] [ERROR]- Internal Server Error: /projects/Notes/
Traceback (most recent call last):
  File "/Users/yujie/anaconda3/envs/django2/lib/python3.6/site-packages/django/core/handlers/exception.py", line 35, in inner
    response = get_response(request)
  File "/Users/yujie/anaconda3/envs/django2/lib/python3.6/site-packages/django/core/handlers/base.py", line 128, in _get_response
    response = self.process_exception_by_middleware(e, request)
  File "/Users/yujie/anaconda3/envs/django2/lib/python3.6/site-packages/django/core/handlers/base.py", line 126, in _get_response
    response = wrapped_callback(request, *callback_args, **callback_kwargs)
  File "/Users/yujie/anaconda3/envs/django2/lib/python3.6/site-packages/django/views/generic/base.py", line 69, in view
    return self.dispatch(request, *args, **kwargs)
  File "/Users/yujie/anaconda3/envs/django2/lib/python3.6/site-packages/django/views/generic/base.py", line 89, in dispatch
    return handler(request, *args, **kwargs)
TypeError: get() got an unexpected keyword argument 'project_name'
2018-01-22 12:17:10,642 [Thread-10:123145329389568] [django.request:118] [exception:handle_uncaught_exception] [ERROR]- Internal Server Error: /projects/Notes/
Traceback (most recent call last):
  File "/Users/yujie/anaconda3/envs/django2/lib/python3.6/site-packages/django/core/handlers/exception.py", line 35, in inner
    response = get_response(request)
  File "/Users/yujie/anaconda3/envs/django2/lib/python3.6/site-packages/django/core/handlers/base.py", line 128, in _get_response
    response = self.process_exception_by_middleware(e, request)
  File "/Users/yujie/anaconda3/envs/django2/lib/python3.6/site-packages/django/core/handlers/base.py", line 126, in _get_response
    response = wrapped_callback(request, *callback_args, **callback_kwargs)
  File "/Users/yujie/anaconda3/envs/django2/lib/python3.6/site-packages/django/views/generic/base.py", line 69, in view
    return self.dispatch(request, *args, **kwargs)
  File "/Users/yujie/anaconda3/envs/django2/lib/python3.6/site-packages/django/views/generic/base.py", line 89, in dispatch
    return handler(request, *args, **kwargs)
TypeError: get() got an unexpected keyword argument 'project_name'
2018-01-22 14:23:47,618 [Thread-7:123145446400000] [django.request:118] [exception:handle_uncaught_exception] [ERROR]- Internal Server Error: /projects/Notes/
Traceback (most recent call last):
  File "/Users/yujie/anaconda3/envs/django2/lib/python3.6/site-packages/django/core/handlers/exception.py", line 35, in inner
    response = get_response(request)
  File "/Users/yujie/anaconda3/envs/django2/lib/python3.6/site-packages/django/core/handlers/base.py", line 128, in _get_response
    response = self.process_exception_by_middleware(e, request)
  File "/Users/yujie/anaconda3/envs/django2/lib/python3.6/site-packages/django/core/handlers/base.py", line 126, in _get_response
    response = wrapped_callback(request, *callback_args, **callback_kwargs)
  File "/Users/yujie/anaconda3/envs/django2/lib/python3.6/site-packages/django/views/generic/base.py", line 69, in view
    return self.dispatch(request, *args, **kwargs)
  File "/Users/yujie/anaconda3/envs/django2/lib/python3.6/site-packages/django/views/generic/base.py", line 89, in dispatch
    return handler(request, *args, **kwargs)
TypeError: get() got an unexpected keyword argument 'name'
2018-01-22 14:40:44,180 [Thread-7:123145500426240] [django.request:118] [exception:handle_uncaught_exception] [ERROR]- Internal Server Error: /projects/Note/
Traceback (most recent call last):
  File "/Users/yujie/anaconda3/envs/django2/lib/python3.6/site-packages/django/core/handlers/exception.py", line 35, in inner
    response = get_response(request)
  File "/Users/yujie/anaconda3/envs/django2/lib/python3.6/site-packages/django/core/handlers/base.py", line 128, in _get_response
    response = self.process_exception_by_middleware(e, request)
  File "/Users/yujie/anaconda3/envs/django2/lib/python3.6/site-packages/django/core/handlers/base.py", line 126, in _get_response
    response = wrapped_callback(request, *callback_args, **callback_kwargs)
  File "/Users/yujie/anaconda3/envs/django2/lib/python3.6/site-packages/django/views/generic/base.py", line 69, in view
    return self.dispatch(request, *args, **kwargs)
  File "/Users/yujie/anaconda3/envs/django2/lib/python3.6/site-packages/django/views/generic/base.py", line 89, in dispatch
    return handler(request, *args, **kwargs)
  File "/Users/yujie/PycharmProjects/Django/Codepedia2/apps/projects/views.py", line 56, in get
    return render(request, 'projects/detail.html', locals())
  File "/Users/yujie/anaconda3/envs/django2/lib/python3.6/site-packages/django/shortcuts.py", line 36, in render
    content = loader.render_to_string(template_name, context, request, using=using)
  File "/Users/yujie/anaconda3/envs/django2/lib/python3.6/site-packages/django/template/loader.py", line 62, in render_to_string
    return template.render(context, request)
  File "/Users/yujie/anaconda3/envs/django2/lib/python3.6/site-packages/django/template/backends/django.py", line 61, in render
    return self.template.render(context)
  File "/Users/yujie/anaconda3/envs/django2/lib/python3.6/site-packages/django/template/base.py", line 175, in render
    return self._render(context)
  File "/Users/yujie/anaconda3/envs/django2/lib/python3.6/site-packages/django/test/utils.py", line 98, in instrumented_test_render
    return self.nodelist.render(context)
  File "/Users/yujie/anaconda3/envs/django2/lib/python3.6/site-packages/django/template/base.py", line 943, in render
    bit = node.render_annotated(context)
  File "/Users/yujie/anaconda3/envs/django2/lib/python3.6/site-packages/django/template/base.py", line 910, in render_annotated
    return self.render(context)
  File "/Users/yujie/anaconda3/envs/django2/lib/python3.6/site-packages/django/template/defaulttags.py", line 167, in render
    values = list(values)
TypeError: 'ProjectInfoView' object is not iterable
2018-01-22 14:48:46,588 [Thread-16:123145541165056] [django.request:118] [exception:handle_uncaught_exception] [ERROR]- Internal Server Error: /projects/Note/
Traceback (most recent call last):
  File "/Users/yujie/anaconda3/envs/django2/lib/python3.6/site-packages/django/core/handlers/exception.py", line 35, in inner
    response = get_response(request)
  File "/Users/yujie/anaconda3/envs/django2/lib/python3.6/site-packages/django/core/handlers/base.py", line 128, in _get_response
    response = self.process_exception_by_middleware(e, request)
  File "/Users/yujie/anaconda3/envs/django2/lib/python3.6/site-packages/django/core/handlers/base.py", line 126, in _get_response
    response = wrapped_callback(request, *callback_args, **callback_kwargs)
  File "/Users/yujie/anaconda3/envs/django2/lib/python3.6/site-packages/django/views/generic/base.py", line 69, in view
    return self.dispatch(request, *args, **kwargs)
  File "/Users/yujie/anaconda3/envs/django2/lib/python3.6/site-packages/django/views/generic/base.py", line 89, in dispatch
    return handler(request, *args, **kwargs)
  File "/Users/yujie/PycharmProjects/Django/Codepedia2/apps/projects/views.py", line 56, in get
    return render(request, 'projects/info.html', locals())
  File "/Users/yujie/anaconda3/envs/django2/lib/python3.6/site-packages/django/shortcuts.py", line 36, in render
    content = loader.render_to_string(template_name, context, request, using=using)
  File "/Users/yujie/anaconda3/envs/django2/lib/python3.6/site-packages/django/template/loader.py", line 62, in render_to_string
    return template.render(context, request)
  File "/Users/yujie/anaconda3/envs/django2/lib/python3.6/site-packages/django/template/backends/django.py", line 61, in render
    return self.template.render(context)
  File "/Users/yujie/anaconda3/envs/django2/lib/python3.6/site-packages/django/template/base.py", line 175, in render
    return self._render(context)
  File "/Users/yujie/anaconda3/envs/django2/lib/python3.6/site-packages/django/test/utils.py", line 98, in instrumented_test_render
    return self.nodelist.render(context)
  File "/Users/yujie/anaconda3/envs/django2/lib/python3.6/site-packages/django/template/base.py", line 943, in render
    bit = node.render_annotated(context)
  File "/Users/yujie/anaconda3/envs/django2/lib/python3.6/site-packages/django/template/base.py", line 910, in render_annotated
    return self.render(context)
  File "/Users/yujie/anaconda3/envs/django2/lib/python3.6/site-packages/django/template/defaulttags.py", line 447, in render
    url = reverse(view_name, args=args, kwargs=kwargs, current_app=current_app)
  File "/Users/yujie/anaconda3/envs/django2/lib/python3.6/site-packages/django/urls/base.py", line 88, in reverse
    return iri_to_uri(resolver._reverse_with_prefix(view, prefix, *args, **kwargs))
  File "/Users/yujie/anaconda3/envs/django2/lib/python3.6/site-packages/django/urls/resolvers.py", line 632, in _reverse_with_prefix
    raise NoReverseMatch(msg)
django.urls.exceptions.NoReverseMatch: Reverse for 'url' not found. 'url' is not a valid view function or pattern name.
2018-01-22 14:49:07,124 [Thread-17:123145530654720] [django.request:118] [exception:handle_uncaught_exception] [ERROR]- Internal Server Error: /projects/Note/
Traceback (most recent call last):
  File "/Users/yujie/anaconda3/envs/django2/lib/python3.6/site-packages/django/core/handlers/exception.py", line 35, in inner
    response = get_response(request)
  File "/Users/yujie/anaconda3/envs/django2/lib/python3.6/site-packages/django/core/handlers/base.py", line 128, in _get_response
    response = self.process_exception_by_middleware(e, request)
  File "/Users/yujie/anaconda3/envs/django2/lib/python3.6/site-packages/django/core/handlers/base.py", line 126, in _get_response
    response = wrapped_callback(request, *callback_args, **callback_kwargs)
  File "/Users/yujie/anaconda3/envs/django2/lib/python3.6/site-packages/django/views/generic/base.py", line 69, in view
    return self.dispatch(request, *args, **kwargs)
  File "/Users/yujie/anaconda3/envs/django2/lib/python3.6/site-packages/django/views/generic/base.py", line 89, in dispatch
    return handler(request, *args, **kwargs)
  File "/Users/yujie/PycharmProjects/Django/Codepedia2/apps/projects/views.py", line 56, in get
    return render(request, 'projects/info.html', locals())
  File "/Users/yujie/anaconda3/envs/django2/lib/python3.6/site-packages/django/shortcuts.py", line 36, in render
    content = loader.render_to_string(template_name, context, request, using=using)
  File "/Users/yujie/anaconda3/envs/django2/lib/python3.6/site-packages/django/template/loader.py", line 62, in render_to_string
    return template.render(context, request)
  File "/Users/yujie/anaconda3/envs/django2/lib/python3.6/site-packages/django/template/backends/django.py", line 61, in render
    return self.template.render(context)
  File "/Users/yujie/anaconda3/envs/django2/lib/python3.6/site-packages/django/template/base.py", line 175, in render
    return self._render(context)
  File "/Users/yujie/anaconda3/envs/django2/lib/python3.6/site-packages/django/test/utils.py", line 98, in instrumented_test_render
    return self.nodelist.render(context)
  File "/Users/yujie/anaconda3/envs/django2/lib/python3.6/site-packages/django/template/base.py", line 943, in render
    bit = node.render_annotated(context)
  File "/Users/yujie/anaconda3/envs/django2/lib/python3.6/site-packages/django/template/base.py", line 910, in render_annotated
    return self.render(context)
  File "/Users/yujie/anaconda3/envs/django2/lib/python3.6/site-packages/django/template/defaulttags.py", line 447, in render
    url = reverse(view_name, args=args, kwargs=kwargs, current_app=current_app)
  File "/Users/yujie/anaconda3/envs/django2/lib/python3.6/site-packages/django/urls/base.py", line 88, in reverse
    return iri_to_uri(resolver._reverse_with_prefix(view, prefix, *args, **kwargs))
  File "/Users/yujie/anaconda3/envs/django2/lib/python3.6/site-packages/django/urls/resolvers.py", line 632, in _reverse_with_prefix
    raise NoReverseMatch(msg)
django.urls.exceptions.NoReverseMatch: Reverse for 'url' not found. 'url' is not a valid view function or pattern name.
2018-01-22 14:49:32,094 [Thread-18:123145530654720] [django.request:118] [exception:handle_uncaught_exception] [ERROR]- Internal Server Error: /projects/Note/
Traceback (most recent call last):
  File "/Users/yujie/anaconda3/envs/django2/lib/python3.6/site-packages/django/core/handlers/exception.py", line 35, in inner
    response = get_response(request)
  File "/Users/yujie/anaconda3/envs/django2/lib/python3.6/site-packages/django/core/handlers/base.py", line 128, in _get_response
    response = self.process_exception_by_middleware(e, request)
  File "/Users/yujie/anaconda3/envs/django2/lib/python3.6/site-packages/django/core/handlers/base.py", line 126, in _get_response
    response = wrapped_callback(request, *callback_args, **callback_kwargs)
  File "/Users/yujie/anaconda3/envs/django2/lib/python3.6/site-packages/django/views/generic/base.py", line 69, in view
    return self.dispatch(request, *args, **kwargs)
  File "/Users/yujie/anaconda3/envs/django2/lib/python3.6/site-packages/django/views/generic/base.py", line 89, in dispatch
    return handler(request, *args, **kwargs)
  File "/Users/yujie/PycharmProjects/Django/Codepedia2/apps/projects/views.py", line 56, in get
    return render(request, 'projects/info.html', locals())
  File "/Users/yujie/anaconda3/envs/django2/lib/python3.6/site-packages/django/shortcuts.py", line 36, in render
    content = loader.render_to_string(template_name, context, request, using=using)
  File "/Users/yujie/anaconda3/envs/django2/lib/python3.6/site-packages/django/template/loader.py", line 62, in render_to_string
    return template.render(context, request)
  File "/Users/yujie/anaconda3/envs/django2/lib/python3.6/site-packages/django/template/backends/django.py", line 61, in render
    return self.template.render(context)
  File "/Users/yujie/anaconda3/envs/django2/lib/python3.6/site-packages/django/template/base.py", line 175, in render
    return self._render(context)
  File "/Users/yujie/anaconda3/envs/django2/lib/python3.6/site-packages/django/test/utils.py", line 98, in instrumented_test_render
    return self.nodelist.render(context)
  File "/Users/yujie/anaconda3/envs/django2/lib/python3.6/site-packages/django/template/base.py", line 943, in render
    bit = node.render_annotated(context)
  File "/Users/yujie/anaconda3/envs/django2/lib/python3.6/site-packages/django/template/base.py", line 910, in render_annotated
    return self.render(context)
  File "/Users/yujie/anaconda3/envs/django2/lib/python3.6/site-packages/django/template/defaulttags.py", line 447, in render
    url = reverse(view_name, args=args, kwargs=kwargs, current_app=current_app)
  File "/Users/yujie/anaconda3/envs/django2/lib/python3.6/site-packages/django/urls/base.py", line 88, in reverse
    return iri_to_uri(resolver._reverse_with_prefix(view, prefix, *args, **kwargs))
  File "/Users/yujie/anaconda3/envs/django2/lib/python3.6/site-packages/django/urls/resolvers.py", line 632, in _reverse_with_prefix
    raise NoReverseMatch(msg)
django.urls.exceptions.NoReverseMatch: Reverse for 'source' with arguments '('Note', '')' not found. 1 pattern(s) tried: ['projects\\/(?P<name>[-a-zA-Z0-9_]+)\\/xref\\/(?P<path>[-a-zA-Z0-9_]+)$']
2018-01-22 14:51:02,850 [Thread-19:123145530654720] [django.request:118] [exception:handle_uncaught_exception] [ERROR]- Internal Server Error: /projects/Note/
Traceback (most recent call last):
  File "/Users/yujie/anaconda3/envs/django2/lib/python3.6/site-packages/django/core/handlers/exception.py", line 35, in inner
    response = get_response(request)
  File "/Users/yujie/anaconda3/envs/django2/lib/python3.6/site-packages/django/core/handlers/base.py", line 128, in _get_response
    response = self.process_exception_by_middleware(e, request)
  File "/Users/yujie/anaconda3/envs/django2/lib/python3.6/site-packages/django/core/handlers/base.py", line 126, in _get_response
    response = wrapped_callback(request, *callback_args, **callback_kwargs)
  File "/Users/yujie/anaconda3/envs/django2/lib/python3.6/site-packages/django/views/generic/base.py", line 69, in view
    return self.dispatch(request, *args, **kwargs)
  File "/Users/yujie/anaconda3/envs/django2/lib/python3.6/site-packages/django/views/generic/base.py", line 89, in dispatch
    return handler(request, *args, **kwargs)
  File "/Users/yujie/PycharmProjects/Django/Codepedia2/apps/projects/views.py", line 56, in get
    return render(request, 'projects/info.html', locals())
  File "/Users/yujie/anaconda3/envs/django2/lib/python3.6/site-packages/django/shortcuts.py", line 36, in render
    content = loader.render_to_string(template_name, context, request, using=using)
  File "/Users/yujie/anaconda3/envs/django2/lib/python3.6/site-packages/django/template/loader.py", line 62, in render_to_string
    return template.render(context, request)
  File "/Users/yujie/anaconda3/envs/django2/lib/python3.6/site-packages/django/template/backends/django.py", line 61, in render
    return self.template.render(context)
  File "/Users/yujie/anaconda3/envs/django2/lib/python3.6/site-packages/django/template/base.py", line 175, in render
    return self._render(context)
  File "/Users/yujie/anaconda3/envs/django2/lib/python3.6/site-packages/django/test/utils.py", line 98, in instrumented_test_render
    return self.nodelist.render(context)
  File "/Users/yujie/anaconda3/envs/django2/lib/python3.6/site-packages/django/template/base.py", line 943, in render
    bit = node.render_annotated(context)
  File "/Users/yujie/anaconda3/envs/django2/lib/python3.6/site-packages/django/template/base.py", line 910, in render_annotated
    return self.render(context)
  File "/Users/yujie/anaconda3/envs/django2/lib/python3.6/site-packages/django/template/defaulttags.py", line 447, in render
    url = reverse(view_name, args=args, kwargs=kwargs, current_app=current_app)
  File "/Users/yujie/anaconda3/envs/django2/lib/python3.6/site-packages/django/urls/base.py", line 88, in reverse
    return iri_to_uri(resolver._reverse_with_prefix(view, prefix, *args, **kwargs))
  File "/Users/yujie/anaconda3/envs/django2/lib/python3.6/site-packages/django/urls/resolvers.py", line 632, in _reverse_with_prefix
    raise NoReverseMatch(msg)
django.urls.exceptions.NoReverseMatch: Reverse for 'source' with arguments '('Note',)' not found. 1 pattern(s) tried: ['projects\\/(?P<name>[-a-zA-Z0-9_]+)\\/xref\\/(?P<path>[-a-zA-Z0-9_]+)$']
2018-01-22 14:51:53,124 [Thread-20:123145530654720] [django.request:118] [exception:handle_uncaught_exception] [ERROR]- Internal Server Error: /projects/Note/
Traceback (most recent call last):
  File "/Users/yujie/anaconda3/envs/django2/lib/python3.6/site-packages/django/core/handlers/exception.py", line 35, in inner
    response = get_response(request)
  File "/Users/yujie/anaconda3/envs/django2/lib/python3.6/site-packages/django/core/handlers/base.py", line 128, in _get_response
    response = self.process_exception_by_middleware(e, request)
  File "/Users/yujie/anaconda3/envs/django2/lib/python3.6/site-packages/django/core/handlers/base.py", line 126, in _get_response
    response = wrapped_callback(request, *callback_args, **callback_kwargs)
  File "/Users/yujie/anaconda3/envs/django2/lib/python3.6/site-packages/django/views/generic/base.py", line 69, in view
    return self.dispatch(request, *args, **kwargs)
  File "/Users/yujie/anaconda3/envs/django2/lib/python3.6/site-packages/django/views/generic/base.py", line 89, in dispatch
    return handler(request, *args, **kwargs)
  File "/Users/yujie/PycharmProjects/Django/Codepedia2/apps/projects/views.py", line 56, in get
    return render(request, 'projects/info.html', locals())
  File "/Users/yujie/anaconda3/envs/django2/lib/python3.6/site-packages/django/shortcuts.py", line 36, in render
    content = loader.render_to_string(template_name, context, request, using=using)
  File "/Users/yujie/anaconda3/envs/django2/lib/python3.6/site-packages/django/template/loader.py", line 62, in render_to_string
    return template.render(context, request)
  File "/Users/yujie/anaconda3/envs/django2/lib/python3.6/site-packages/django/template/backends/django.py", line 61, in render
    return self.template.render(context)
  File "/Users/yujie/anaconda3/envs/django2/lib/python3.6/site-packages/django/template/base.py", line 175, in render
    return self._render(context)
  File "/Users/yujie/anaconda3/envs/django2/lib/python3.6/site-packages/django/test/utils.py", line 98, in instrumented_test_render
    return self.nodelist.render(context)
  File "/Users/yujie/anaconda3/envs/django2/lib/python3.6/site-packages/django/template/base.py", line 943, in render
    bit = node.render_annotated(context)
  File "/Users/yujie/anaconda3/envs/django2/lib/python3.6/site-packages/django/template/base.py", line 910, in render_annotated
    return self.render(context)
  File "/Users/yujie/anaconda3/envs/django2/lib/python3.6/site-packages/django/template/defaulttags.py", line 447, in render
    url = reverse(view_name, args=args, kwargs=kwargs, current_app=current_app)
  File "/Users/yujie/anaconda3/envs/django2/lib/python3.6/site-packages/django/urls/base.py", line 88, in reverse
    return iri_to_uri(resolver._reverse_with_prefix(view, prefix, *args, **kwargs))
  File "/Users/yujie/anaconda3/envs/django2/lib/python3.6/site-packages/django/urls/resolvers.py", line 632, in _reverse_with_prefix
    raise NoReverseMatch(msg)
django.urls.exceptions.NoReverseMatch: Reverse for 'source' with arguments '('Note', '/')' not found. 1 pattern(s) tried: ['projects\\/(?P<name>[-a-zA-Z0-9_]+)\\/xref\\/(?P<path>[-a-zA-Z0-9_]+)$']
2018-01-22 15:19:43,278 [Thread-7:123145541103616] [django.request:118] [exception:handle_uncaught_exception] [ERROR]- Internal Server Error: /projects/Note/xref/
Traceback (most recent call last):
  File "/Users/yujie/anaconda3/envs/django2/lib/python3.6/site-packages/django/core/handlers/exception.py", line 35, in inner
    response = get_response(request)
  File "/Users/yujie/anaconda3/envs/django2/lib/python3.6/site-packages/django/core/handlers/base.py", line 128, in _get_response
    response = self.process_exception_by_middleware(e, request)
  File "/Users/yujie/anaconda3/envs/django2/lib/python3.6/site-packages/django/core/handlers/base.py", line 126, in _get_response
    response = wrapped_callback(request, *callback_args, **callback_kwargs)
  File "/Users/yujie/anaconda3/envs/django2/lib/python3.6/site-packages/django/views/generic/base.py", line 69, in view
    return self.dispatch(request, *args, **kwargs)
  File "/Users/yujie/anaconda3/envs/django2/lib/python3.6/site-packages/django/views/generic/base.py", line 89, in dispatch
    return handler(request, *args, **kwargs)
TypeError: get() missing 1 required positional argument: 'path'
2018-01-22 15:24:08,249 [Thread-20:123145517735936] [django.request:118] [exception:handle_uncaught_exception] [ERROR]- Internal Server Error: /projects/4/xref//res/values-zh-rTW/
Traceback (most recent call last):
  File "/Users/yujie/anaconda3/envs/django2/lib/python3.6/site-packages/django/core/handlers/exception.py", line 35, in inner
    response = get_response(request)
  File "/Users/yujie/anaconda3/envs/django2/lib/python3.6/site-packages/django/core/handlers/base.py", line 128, in _get_response
    response = self.process_exception_by_middleware(e, request)
  File "/Users/yujie/anaconda3/envs/django2/lib/python3.6/site-packages/django/core/handlers/base.py", line 126, in _get_response
    response = wrapped_callback(request, *callback_args, **callback_kwargs)
  File "/Users/yujie/anaconda3/envs/django2/lib/python3.6/site-packages/django/views/generic/base.py", line 69, in view
    return self.dispatch(request, *args, **kwargs)
  File "/Users/yujie/anaconda3/envs/django2/lib/python3.6/site-packages/django/views/generic/base.py", line 89, in dispatch
    return handler(request, *args, **kwargs)
  File "/Users/yujie/PycharmProjects/Django/Codepedia2/apps/projects/views.py", line 64, in get
    if file.type == '1':
AttributeError: 'NoneType' object has no attribute 'type'
2018-01-22 15:24:33,973 [Thread-7:123145528385536] [django.request:118] [exception:handle_uncaught_exception] [ERROR]- Internal Server Error: /projects/4/xref//res/values-zh-rTW/
Traceback (most recent call last):
  File "/Users/yujie/anaconda3/envs/django2/lib/python3.6/site-packages/django/core/handlers/exception.py", line 35, in inner
    response = get_response(request)
  File "/Users/yujie/anaconda3/envs/django2/lib/python3.6/site-packages/django/core/handlers/base.py", line 128, in _get_response
    response = self.process_exception_by_middleware(e, request)
  File "/Users/yujie/anaconda3/envs/django2/lib/python3.6/site-packages/django/core/handlers/base.py", line 126, in _get_response
    response = wrapped_callback(request, *callback_args, **callback_kwargs)
  File "/Users/yujie/anaconda3/envs/django2/lib/python3.6/site-packages/django/views/generic/base.py", line 69, in view
    return self.dispatch(request, *args, **kwargs)
  File "/Users/yujie/anaconda3/envs/django2/lib/python3.6/site-packages/django/views/generic/base.py", line 89, in dispatch
    return handler(request, *args, **kwargs)
  File "/Users/yujie/PycharmProjects/Django/Codepedia2/apps/projects/views.py", line 64, in get
    if file.type == '1':
AttributeError: 'NoneType' object has no attribute 'type'
2018-01-22 15:25:06,541 [Thread-8:123145528385536] [django.request:118] [exception:handle_uncaught_exception] [ERROR]- Internal Server Error: /projects/4/xref//res/values-zh-rTW/
Traceback (most recent call last):
  File "/Users/yujie/anaconda3/envs/django2/lib/python3.6/site-packages/django/core/handlers/exception.py", line 35, in inner
    response = get_response(request)
  File "/Users/yujie/anaconda3/envs/django2/lib/python3.6/site-packages/django/core/handlers/base.py", line 128, in _get_response
    response = self.process_exception_by_middleware(e, request)
  File "/Users/yujie/anaconda3/envs/django2/lib/python3.6/site-packages/django/core/handlers/base.py", line 126, in _get_response
    response = wrapped_callback(request, *callback_args, **callback_kwargs)
  File "/Users/yujie/anaconda3/envs/django2/lib/python3.6/site-packages/django/views/generic/base.py", line 69, in view
    return self.dispatch(request, *args, **kwargs)
  File "/Users/yujie/anaconda3/envs/django2/lib/python3.6/site-packages/django/views/generic/base.py", line 89, in dispatch
    return handler(request, *args, **kwargs)
  File "/Users/yujie/PycharmProjects/Django/Codepedia2/apps/projects/views.py", line 64, in get
    if file.type == '1':
AttributeError: 'NoneType' object has no attribute 'type'
2018-01-22 15:25:06,555 [Thread-9:123145533640704] [django.request:118] [exception:handle_uncaught_exception] [ERROR]- Internal Server Error: /projects/Note/xref/res/
Traceback (most recent call last):
  File "/Users/yujie/anaconda3/envs/django2/lib/python3.6/site-packages/django/core/handlers/exception.py", line 35, in inner
    response = get_response(request)
  File "/Users/yujie/anaconda3/envs/django2/lib/python3.6/site-packages/django/core/handlers/base.py", line 128, in _get_response
    response = self.process_exception_by_middleware(e, request)
  File "/Users/yujie/anaconda3/envs/django2/lib/python3.6/site-packages/django/core/handlers/base.py", line 126, in _get_response
    response = wrapped_callback(request, *callback_args, **callback_kwargs)
  File "/Users/yujie/anaconda3/envs/django2/lib/python3.6/site-packages/django/views/generic/base.py", line 69, in view
    return self.dispatch(request, *args, **kwargs)
  File "/Users/yujie/anaconda3/envs/django2/lib/python3.6/site-packages/django/views/generic/base.py", line 89, in dispatch
    return handler(request, *args, **kwargs)
  File "/Users/yujie/PycharmProjects/Django/Codepedia2/apps/projects/views.py", line 64, in get
    if file.type == '1':
AttributeError: 'NoneType' object has no attribute 'type'
2018-01-22 15:38:44,484 [Thread-7:123145407143936] [django.request:118] [exception:handle_uncaught_exception] [ERROR]- Internal Server Error: /projects/Note/xref/res/values-zh-rTW/arrays.xml/
Traceback (most recent call last):
  File "/Users/yujie/anaconda3/envs/django2/lib/python3.6/site-packages/django/core/handlers/exception.py", line 35, in inner
    response = get_response(request)
  File "/Users/yujie/anaconda3/envs/django2/lib/python3.6/site-packages/django/core/handlers/base.py", line 128, in _get_response
    response = self.process_exception_by_middleware(e, request)
  File "/Users/yujie/anaconda3/envs/django2/lib/python3.6/site-packages/django/core/handlers/base.py", line 126, in _get_response
    response = wrapped_callback(request, *callback_args, **callback_kwargs)
  File "/Users/yujie/anaconda3/envs/django2/lib/python3.6/site-packages/django/views/generic/base.py", line 69, in view
    return self.dispatch(request, *args, **kwargs)
  File "/Users/yujie/anaconda3/envs/django2/lib/python3.6/site-packages/django/views/generic/base.py", line 89, in dispatch
    return handler(request, *args, **kwargs)
  File "/Users/yujie/PycharmProjects/Django/Codepedia2/apps/projects/views.py", line 69, in get
    with open(abspath,'r') as f:
FileNotFoundError: [Errno 2] No such file or directory: '/Users/yujie/workspace/source/Notes/res/values-zh-rTW/arrays.xml'
2018-01-22 15:39:14,544 [Thread-7:123145566384128] [django.request:118] [exception:handle_uncaught_exception] [ERROR]- Internal Server Error: /projects/Note/xref/res/values-zh-rTW/arrays.xml/
Traceback (most recent call last):
  File "/Users/yujie/anaconda3/envs/django2/lib/python3.6/site-packages/django/core/handlers/exception.py", line 35, in inner
    response = get_response(request)
  File "/Users/yujie/anaconda3/envs/django2/lib/python3.6/site-packages/django/core/handlers/base.py", line 128, in _get_response
    response = self.process_exception_by_middleware(e, request)
  File "/Users/yujie/anaconda3/envs/django2/lib/python3.6/site-packages/django/core/handlers/base.py", line 126, in _get_response
    response = wrapped_callback(request, *callback_args, **callback_kwargs)
  File "/Users/yujie/anaconda3/envs/django2/lib/python3.6/site-packages/django/views/generic/base.py", line 69, in view
    return self.dispatch(request, *args, **kwargs)
  File "/Users/yujie/anaconda3/envs/django2/lib/python3.6/site-packages/django/views/generic/base.py", line 89, in dispatch
    return handler(request, *args, **kwargs)
  File "/Users/yujie/PycharmProjects/Django/Codepedia2/apps/projects/views.py", line 70, in get
    code = f.read()
  File "/Users/yujie/anaconda3/envs/django2/lib/python3.6/encodings/ascii.py", line 26, in decode
    return codecs.ascii_decode(input, self.errors)[0]
UnicodeDecodeError: 'ascii' codec can't decode byte 0xe7 in position 764: ordinal not in range(128)
2018-01-22 15:39:32,076 [Thread-7:123145508323328] [django.request:118] [exception:handle_uncaught_exception] [ERROR]- Internal Server Error: /projects/Note/xref/res/values-zh-rTW/arrays.xml/
Traceback (most recent call last):
  File "/Users/yujie/anaconda3/envs/django2/lib/python3.6/site-packages/django/core/handlers/exception.py", line 35, in inner
    response = get_response(request)
  File "/Users/yujie/anaconda3/envs/django2/lib/python3.6/site-packages/django/core/handlers/base.py", line 128, in _get_response
    response = self.process_exception_by_middleware(e, request)
  File "/Users/yujie/anaconda3/envs/django2/lib/python3.6/site-packages/django/core/handlers/base.py", line 126, in _get_response
    response = wrapped_callback(request, *callback_args, **callback_kwargs)
  File "/Users/yujie/anaconda3/envs/django2/lib/python3.6/site-packages/django/views/generic/base.py", line 69, in view
    return self.dispatch(request, *args, **kwargs)
  File "/Users/yujie/anaconda3/envs/django2/lib/python3.6/site-packages/django/views/generic/base.py", line 89, in dispatch
    return handler(request, *args, **kwargs)
  File "/Users/yujie/PycharmProjects/Django/Codepedia2/apps/projects/views.py", line 70, in get
    code = f.read()
io.UnsupportedOperation: not readable
2018-01-22 15:40:47,618 [Thread-7:123145540829184] [django.request:118] [exception:handle_uncaught_exception] [ERROR]- Internal Server Error: /projects/Note/xref/res/values-zh-rTW/arrays.xml/
Traceback (most recent call last):
  File "/Users/yujie/anaconda3/envs/django2/lib/python3.6/site-packages/django/core/handlers/exception.py", line 35, in inner
    response = get_response(request)
  File "/Users/yujie/anaconda3/envs/django2/lib/python3.6/site-packages/django/core/handlers/base.py", line 128, in _get_response
    response = self.process_exception_by_middleware(e, request)
  File "/Users/yujie/anaconda3/envs/django2/lib/python3.6/site-packages/django/core/handlers/base.py", line 126, in _get_response
    response = wrapped_callback(request, *callback_args, **callback_kwargs)
  File "/Users/yujie/anaconda3/envs/django2/lib/python3.6/site-packages/django/views/generic/base.py", line 69, in view
    return self.dispatch(request, *args, **kwargs)
  File "/Users/yujie/anaconda3/envs/django2/lib/python3.6/site-packages/django/views/generic/base.py", line 89, in dispatch
    return handler(request, *args, **kwargs)
  File "/Users/yujie/PycharmProjects/Django/Codepedia2/apps/projects/views.py", line 70, in get
    print(f.read())
  File "/Users/yujie/anaconda3/envs/django2/lib/python3.6/encodings/ascii.py", line 26, in decode
    return codecs.ascii_decode(input, self.errors)[0]
UnicodeDecodeError: 'ascii' codec can't decode byte 0xe7 in position 764: ordinal not in range(128)
